Workbook

Sheet HuongDan
A1: Bộ test case thủ công — Office và PDF
A2: Phạm vi Office | C2: Mở và xem Word / Excel / PowerPoint, tạo tài liệu mới, chế độ sửa (ribbon, lưu, bản nháp), tìm và thay thế, ô công thức Excel, sửa và sắp xếp slide, trình chiếu, chuyển sang PDF.
A3: Phạm vi PDF | C3: Trình đọc (tìm kiếm, mục lục, đánh dấu, màu trang, Text view, đọc thành tiếng, tự cuộn), sửa tại chỗ (thêm chữ, ghi chú, ký, điền form, sắp xếp trang), 11 công cụ (Merge, Split, Compress, Protect, Watermark, Redact, OCR, Translate, PDF to images, Images to PDF, ZIP), chọn file, màn xử lý / kết quả, scanner.
A4: Nguồn | C4: Kết quả mong đợi viết từ việc đọc code của app và source SDK, chưa chạy trên thiết bị. Ở phần PDF, tên nút được mô tả theo chức năng vì nhiều nút chỉ có biểu tượng.
A5: Chuỗi hiển thị | C5: Các câu trong ngoặc kép là chuỗi tiếng Anh mặc định của app. Nếu dùng ngôn ngữ khác, đối chiếu theo nghĩa.
A7: Các sheet
A8: TongHop | C8: Tự đếm Pass / Fail / Blocked / chưa chạy của mọi sheet.
A9: Office_EndUser | B9: 27 kịch bản, theo bước | C9: Kịch bản theo việc người dùng muốn làm với file Office. Mỗi dòng là 1 bước có kết quả mong đợi riêng.
A10: PDF_EndUser | B10: 32 kịch bản, theo bước | C10: Kịch bản người dùng cho đọc, sửa, công cụ PDF và scanner.
A11: Office_Chung, Office_Word, Office_Excel, Office_PowerPoint, Office_Slideshow | B11: theo ca | C11: Từng tính năng Office riêng lẻ và các giá trị biên. Mã trong cột Lưu ý của Office_EndUser (vd PP-016, GEN-022) trỏ tới ca ở các sheet này.
A12: PDF_BienVaLoi | B12: theo ca | C12: Ca biên, lỗi và tình huống bất thường của các tính năng PDF.
A14: Cách chạy
A15: Sheet *_EndUser | C15: Chạy các bước theo đúng thứ tự trong 1 kịch bản và đánh kết quả cho từng bước. Bước Fail mà vẫn đi tiếp được thì đi tiếp; không đi tiếp được thì đánh Blocked cho các bước sau.
A16: Các sheet còn lại | C16: Mỗi dòng là 1 ca độc lập. Chạy ca ưu tiên Cao trước (với các sheet có cột Ưu tiên).
A18: Cách điền
A19: Cột được điền | B19: Kết quả, Thực tế / ghi chú của tester, Thiết bị / bản build | C19: Ba cột nền vàng nhạt. Các cột khác không cần sửa.
A20: Kết quả | B20: Pass | C20: Đúng toàn bộ phần mong đợi.
B21: Fail | C21: Sai bất kỳ ý nào; mô tả điều thực tế, kèm ảnh/video nếu có.
B22: Blocked | C22: Không chạy được vì bước/ca khác lỗi hoặc thiếu dữ liệu test.
B23: N/A | C23: Không áp dụng cho bản build/thiết bị này.
A24: Nhãn (cột Loại hoặc Lưu ý) | B24: Lỗi đã biết | C24: Lỗi đã biết từ phân tích code (nền cam). Phần mong đợi ghi cả MONG ĐỢI và HIỆN TẠI; đánh Fail nếu vẫn xảy ra như HIỆN TẠI.
B25: Cần xác nhận | C25: Hành vi chưa xác định chắc từ code (nền xanh nhạt). Ghi lại điều thực tế để chốt yêu cầu.
B26: Giới hạn | C26: Giới hạn hiện tại của sản phẩm, không phải lỗi (nền xám). Đánh Pass nếu đúng như mô tả.
A28: Ví dụ một dòng đã điền
A29: ID | B29: PP-016 (sheet Office_PowerPoint)
A30: Kết quả | B30: Fail
A31: Thực tế / ghi chú | B31: Nhảy về slide 1 ngay khi bàn phím bật; ô nhập hiện ở slide 1. Video: bug_pp016.mp4
A32: Thiết bị / bản build | B32: Galaxy A54, Android 14 — devDebug (12/10)
A34: Dữ liệu test — Office (mã F)
A35: Mã | B35: Tên | C35: Mô tả
A36: F01 | B36: Word ngắn | C36: .docx 1–2 trang, chỉ chữ
A37: F02 | B37: Word dài | C37: .docx ≥ 20 trang, có bảng, ảnh, header/footer, text box
A38: F03 | B38: Word cũ | C38: .doc
A39: F04 | B39: Excel | C39: .xlsx ≥ 3 sheet, có công thức (SUM, AVERAGE, IF), ô gộp, ≥ 1000 dòng
A40: F05 | B40: Excel macro | C40: .xlsm có 1 macro đơn giản
A41: F06 | B41: Excel cũ | C41: .xls
A42: F07 | B42: PowerPoint | C42: .pptx ≥ 5 slide, có ảnh, text box, shape chồng nhau, shape group, hiệu ứng (Entrance theo click) và transition
A43: F08 | B43: PowerPoint nặng | C43: .pptx ≥ 30 slide, nhiều ảnh lớn
A44: F09 | B44: PowerPoint cũ | C44: .ppt
A45: F10 | B45: Có mật khẩu (Word) | C45: .docx đặt mật khẩu mở bằng MS Word (ghi lại mật khẩu)
...

Sheet TongHop
A1: Sheet | B1: Tổng số dòng | C1: Pass | D1: Fail | E1: Blocked | F1: N/A | G1: Chưa chạy | H1: % đã chạy | I1: Lỗi đã biết | J1: Cần xác nhận | K1: Giới hạn
A2: Office_EndUser | B2: =COUNTA(Office_EndUser!A2:A223) | C2: =COUNTIF(Office_EndUser!H2:H223,"Pass") | D2: =COUNTIF(Office_EndUser!H2:H223,"Fail") | E2: =COUNTIF(Office_EndUser!H2:H223,"Blocked") | F2: =COUNTIF(Office_EndUser!H2:H223,"N/A") | G2: =B2-SUM(C2:F2) | H2: =IF(B2=0,0,SUM(C2:F2)/B2) | I2: =COUNTIF(Office_EndUser!G2:G223,"Lỗi đã biết*") | J2: =COUNTIF(Office_EndUser!G2:G223,"Cần xác nhận*") | K2: =COUNTIF(Office_EndUser!G2:G223,"Giới hạn*")
A3: Office_Chung | B3: =COUNTA(Office_Chung!A2:A83) | C3: =COUNTIF(Office_Chung!J2:J83,"Pass") | D3: =COUNTIF(Office_Chung!J2:J83,"Fail") | E3: =COUNTIF(Office_Chung!J2:J83,"Blocked") | F3: =COUNTIF(Office_Chung!J2:J83,"N/A") | G3: =B3-SUM(C3:F3) | H3: =IF(B3=0,0,SUM(C3:F3)/B3) | I3: =COUNTIF(Office_Chung!D2:D83,"Lỗi đã biết") | J3: =COUNTIF(Office_Chung!D2:D83,"Cần xác nhận") | K3: =COUNTIF(Office_Chung!D2:D83,"Giới hạn")
A4: Office_Word | B4: =COUNTA(Office_Word!A2:A53) | C4: =COUNTIF(Office_Word!J2:J53,"Pass") | D4: =COUNTIF(Office_Word!J2:J53,"Fail") | E4: =COUNTIF(Office_Word!J2:J53,"Blocked") | F4: =COUNTIF(Office_Word!J2:J53,"N/A") | G4: =B4-SUM(C4:F4) | H4: =IF(B4=0,0,SUM(C4:F4)/B4) | I4: =COUNTIF(Office_Word!D2:D53,"Lỗi đã biết") | J4: =COUNTIF(Office_Word!D2:D53,"Cần xác nhận") | K4: =COUNTIF(Office_Word!D2:D53,"Giới hạn")
A5: Office_Excel | B5: =COUNTA(Office_Excel!A2:A39) | C5: =COUNTIF(Office_Excel!J2:J39,"Pass") | D5: =COUNTIF(Office_Excel!J2:J39,"Fail") | E5: =COUNTIF(Office_Excel!J2:J39,"Blocked") | F5: =COUNTIF(Office_Excel!J2:J39,"N/A") | G5: =B5-SUM(C5:F5) | H5: =IF(B5=0,0,SUM(C5:F5)/B5) | I5: =COUNTIF(Office_Excel!D2:D39,"Lỗi đã biết") | J5: =COUNTIF(Office_Excel!D2:D39,"Cần xác nhận") | K5: =COUNTIF(Office_Excel!D2:D39,"Giới hạn")
A6: Office_PowerPoint | B6: =COUNTA(Office_PowerPoint!A2:A64) | C6: =COUNTIF(Office_PowerPoint!J2:J64,"Pass") | D6: =COUNTIF(Office_PowerPoint!J2:J64,"Fail") | E6: =COUNTIF(Office_PowerPoint!J2:J64,"Blocked") | F6: =COUNTIF(Office_PowerPoint!J2:J64,"N/A") | G6: =B6-SUM(C6:F6) | H6: =IF(B6=0,0,SUM(C6:F6)/B6) | I6: =COUNTIF(Office_PowerPoint!D2:D64,"Lỗi đã biết") | J6: =COUNTIF(Office_PowerPoint!D2:D64,"Cần xác nhận") | K6: =COUNTIF(Office_PowerPoint!D2:D64,"Giới hạn")
A7: Office_Slideshow | B7: =COUNTA(Office_Slideshow!A2:A30) | C7: =COUNTIF(Office_Slideshow!J2:J30,"Pass") | D7: =COUNTIF(Office_Slideshow!J2:J30,"Fail") | E7: =COUNTIF(Office_Slideshow!J2:J30,"Blocked") | F7: =COUNTIF(Office_Slideshow!J2:J30,"N/A") | G7: =B7-SUM(C7:F7) | H7: =IF(B7=0,0,SUM(C7:F7)/B7) | I7: =COUNTIF(Office_Slideshow!D2:D30,"Lỗi đã biết") | J7: =COUNTIF(Office_Slideshow!D2:D30,"Cần xác nhận") | K7: =COUNTIF(Office_Slideshow!D2:D30,"Giới hạn")
A8: PDF_EndUser | B8: =COUNTA(PDF_EndUser!A2:A292) | C8: =COUNTIF(PDF_EndUser!H2:H292,"Pass") | D8: =COUNTIF(PDF_EndUser!H2:H292,"Fail") | E8: =COUNTIF(PDF_EndUser!H2:H292,"Blocked") | F8: =COUNTIF(PDF_EndUser!H2:H292,"N/A") | G8: =B8-SUM(C8:F8) | H8: =IF(B8=0,0,SUM(C8:F8)/B8) | I8: =COUNTIF(PDF_EndUser!G2:G292,"Lỗi đã biết*") | J8: =COUNTIF(PDF_EndUser!G2:G292,"Cần xác nhận*") | K8: =COUNTIF(PDF_EndUser!G2:G292,"Giới hạn*")
A9: PDF_BienVaLoi | B9: =COUNTA(PDF_BienVaLoi!A2:A89) | C9: =COUNTIF(PDF_BienVaLoi!H2:H89,"Pass") | D9: =COUNTIF(PDF_BienVaLoi!H2:H89,"Fail") | E9: =COUNTIF(PDF_BienVaLoi!H2:H89,"Blocked") | F9: =COUNTIF(PDF_BienVaLoi!H2:H89,"N/A") | G9: =B9-SUM(C9:F9) | H9: =IF(B9=0,0,SUM(C9:F9)/B9) | I9: =COUNTIF(PDF_BienVaLoi!G2:G89,"Lỗi đã biết*") | J9: =COUNTIF(PDF_BienVaLoi!G2:G89,"Cần xác nhận*") | K9: =COUNTIF(PDF_BienVaLoi!G2:G89,"Giới hạn*")
A10: Tổng | B10: =SUM(B2:B9) | C10: =SUM(C2:C9) | D10: =SUM(D2:D9) | E10: =SUM(E2:E9) | F10: =SUM(F2:F9) | G10: =SUM(G2:G9) | H10: =IF(B10=0,0,SUM(C10:F10)/B10) | I10: =SUM(I2:I9) | J10: =SUM(J2:J9) | K10: =SUM(K2:K9)
A12: Các số tự tính từ cột "Kết quả" và cột "Loại" / "Lưu ý" của từng sheet. Sheet *_EndUser đếm theo bước, các sheet còn lại đếm theo ca.

Sheet Office_EndUser
A1: ID bước | B1: Kịch bản | C1: Mục tiêu của người dùng | D1: Chuẩn bị | E1: Người dùng làm gì | F1: Người dùng thấy gì (mong đợi) | G1: Lưu ý | H1: Kết quả | I1: Thực tế / ghi chú của tester | J1: Thiết bị / bản build
A2: E01-01 | B2: E01. Mở file Word nhận từ app khác | C2: Tôi nhận được 1 file Word qua Zalo/Gmail và muốn đọc ngay. | D2: Có 1 file .docx trong tin nhắn Zalo hoặc email. App đã cài và đã qua màn chào. | E2: Trong Zalo/Gmail, chạm vào file .docx. | F2: Điện thoại hỏi mở bằng app nào, trong danh sách có app này. | H2: Pass
A3: E01-02 | E3: Chọn app này. | F3: Thấy màn chờ ngắn rồi tài liệu hiện ra ngay, không phải đi qua màn hình chính của app. | H3: Pass
A4: E01-03 | E4: Nhìn thanh trên cùng. | F4: Có nút quay lại, biểu tượng Word, tên file, nút tìm kiếm (kính lúp), nút chia sẻ và nút ⋮. Góc dưới có nút Edit. Có nhãn "Page 1 / N". | H4: Pass
A5: E01-04 | E5: Vuốt lên để đọc tiếp. | F5: Trang cuộn mượt, nhãn số trang tăng dần. | H5: Pass
A6: E01-05 | E6: Chụm 2 ngón để thu nhỏ, giãn để phóng to. | F6: Chữ to/nhỏ theo tay và nét lại sau khi thả. | H6: Pass
A7: E01-06 | E7: Bấm nút quay lại. | F7: Quay về đúng Zalo/Gmail nơi vừa bấm vào file. | H7: Pass
A8: E02-01 | B8: E02. Đọc tài liệu dài và tìm lại sau này | C8: Tôi đọc 1 tài liệu dài, muốn nhảy nhanh tới trang cần và đánh dấu để lần sau mở lại. | D8: Đã cấp quyền bộ nhớ. Có file F02 (Word ≥ 20 trang) trong máy. | E8: Mở app, vào tab Files, chạm F02. | F8: Tài liệu mở ở chế độ đọc. | H8: Pass
A9: E02-02 | E9: Bấm ⋮ → Go to page. | F9: Hộp nhập số hiện ra, có sẵn số trang đang đọc. | H9: Pass
A10: E02-03 | E10: Nhập 15, bấm Done. | F10: Tài liệu nhảy tới trang 15, nhãn "Page 15 / N". | H10: Pass
A11: E02-04 | E11: Bấm ⋮ → Go to page, nhập 999, Done. | F11: Thông báo "Enter a number from 1 to N"; vẫn ở trang 15. | H11: Pass
A12: E02-05 | E12: Bấm ⋮ → Favorite. | F12: Menu đóng. Mở lại ⋮ thấy mục Favorite đã ở trạng thái đã đánh dấu. | H12: Pass
A13: E02-06 | E13: Bấm ⋮ → File info. | F13: Bảng thông tin hiện tên, nơi lưu, dung lượng, ngày sửa của file. | H13: Pass
A14: E02-07 | E14: Đóng bảng, bấm quay lại, mở danh sách Favorite. | F14: F02 có trong danh sách yêu thích. | H14: Pass
A15: E02-08 | E15: Xem danh sách Recent. | F15: F02 nằm trên cùng. | H15: Fail | I15: mở file word nhưng không hiện (F02)
A16: E03-01 | B16: E03. Soạn một lá đơn bằng Word | C16: Tôi cần viết nhanh 1 lá đơn xin nghỉ phép trên điện thoại rồi gửi cho sếp. | D16: Đã cấp quyền bộ nhớ. Bàn phím tiếng Việt (Telex). | E16: Ở tab Files bấm nút tạo mới (+) → chọn tạo tài liệu. | F16: Màn New document: tên gợi ý "Untitled-<tháng>-<ngày>", loại Word đang được chọn, đuôi .docx, có dòng cho biết nơi lưu. | H16: Pass
A17: E03-02 | E17: Sửa tên thành "Don xin nghi phep", bấm Create. | F17: Tài liệu trắng mở ra, sẵn sàng gõ: có thanh công cụ (ribbon) ở dưới, góc trên ghi "Saved". | H17: Pass
A18: E03-03 | E18: Chạm vào trang, gõ "ĐƠN XIN NGHỈ PHÉP" rồi Enter. | F18: Bàn phím bật, thanh công cụ nằm ngay trên bàn phím. Chữ có dấu hiện đúng. Góc trên đổi thành "Not saved". | H18: Fail | I18: Luôn hiện chữ Save
A19: E03-04 | E19: Gõ tiếp 3 đoạn nội dung (kính gửi, lý do, thời gian). | F19: Chữ hiện đúng, tự xuống dòng khi hết lề; con trỏ luôn nằm trong vùng nhìn thấy. | H19: Pass
A20: E03-05 | E20: Nhấn giữ vào dòng tiêu đề để chọn, kéo tay nắm chọn hết dòng. | F20: Dòng tiêu đề được tô chọn. | H20: Pass
A21: E03-06 | E21: Ở tab Home bấm B, rồi chạm ô Size và chọn 20. | F21: Tiêu đề đậm và to hơn; nút B sáng; ô Size hiện "20". | H21: Pass
A22: E03-07 | E22: Sang tab Layout, bấm căn giữa. | F22: Tiêu đề ra giữa trang; nút căn giữa sáng. | H22: Pass
A23: E03-08 | E23: Chọn 3 đoạn nội dung, bấm căn đều 2 bên. | F23: Ba đoạn thẳng cả lề trái và phải. | H23: Pass
A24: E03-09 | E24: Chạm ô Font, chọn 1 font khác. | F24: Chữ đang chọn đổi kiểu; ô Font hiện tên font vừa chọn. | H24: Pass
A25: E03-10 | E25: Bấm nút Save ở góc trên → Save. | F25: Thông báo "Saved"; góc trên ghi "Saved". | H25: Pass
A26: E03-11 | E26: Bấm Save → Share, chọn Gmail. | F26: Gmail mở ra với file đơn đính kèm sẵn. | H26: Pass
A27: E03-12 | E27: Quay lại app, bấm nút quay lại 2 lần về Files. | F27: Không bị hỏi lưu (vì đã lưu). File "Don xin nghi phep.docx" có trong danh sách. | H27: Pass
A28: E03-13 | E28: Tắt hẳn app, mở lại và mở file vừa tạo. | F28: Nội dung và định dạng y như lúc lưu. | H28: Fail | I28: Text (don xin nghi phep) format cân giữa qoay lại căn lền trái
A29: E04-01 | B29: E04. Làm báo cáo có bảng và ảnh | C29: Tôi muốn thêm 1 bảng số liệu và 1 ảnh chụp hiện trường vào báo cáo. | D29: Mở F01, bấm Edit. Có ảnh trong thư viện. | E29: Đặt con trỏ ở cuối tài liệu, sang tab Insert, bấm Table. | F29: Bàn phím ẩn, hiện bảng chọn kích thước. | H29: Pass
A30: E04-02 | E30: Chọn 3 hàng × 3 cột. | F30: Bảng 3×3 xuất hiện tại vị trí con trỏ. | H30: Fail | I30: Phải thêm bảng lần 2 tghì mới hiện 2 bảng, tư thêm 1 trang nmứi và bảng ở page 2
A31: E04-03 | E31: Chạm từng ô và gõ nội dung. | F31: Chữ vào đúng ô; ô tự cao lên khi gõ nhiều dòng. | H31: Pass
A32: E04-04 | E32: Đặt con trỏ ở hàng 2, sang tab Table, bấm thêm hàng phía dưới. | F32: Có thêm 1 hàng trống ngay dưới hàng 2. | G32: Cần xác nhận: tab Table có luôn hiện không, hay chỉ khi tài liệu đã có bảng lúc bấm Edit. | H32: Pass
A33: E04-05 | E33: Bấm thêm cột bên phải. | F33: Có thêm 1 cột trống bên phải ô đang đứng. | H33: Pass
A34: E04-06 | E34: Bấm xoá hàng, rồi xoá cột. | F34: Hàng và cột đang đứng bị xoá, phần còn lại không xô lệch. | H34: Pass
A35: E04-07 | E35: Đặt con trỏ dưới bảng, tab Insert → Picture, chọn 1 ảnh. | F35: Ảnh hiện trong tài liệu, không méo. | H35: Pass
A36: E04-08 | E36: Tab Insert → Camera, chụp 1 tấm, xác nhận. | F36: Ảnh vừa chụp được chèn vào tài liệu. | H36: Pass
A37: E04-09 | E37: Tab Insert → Camera rồi bấm quay lại không chụp. | F37: Trở về tài liệu, không có gì thay đổi. | H37: Fail | I37: attemp save: can not get object class | K37: Không bấm lưu dược, không xoá đựơcj ảnh đã then
A38: E04-10 | E38: Save → Save. Đóng và mở lại file. | F38: Bảng và 2 ảnh còn nguyên vị trí.
A39: E05-01 | B39: E05. Sửa một từ sai trong cả tài liệu | C39: Tôi gõ sai tên công ty ở nhiều chỗ và muốn sửa hết một lần. | D39: Mở F02 ở chế độ đọc; biết 1 từ xuất hiện nhiều lần. | E39: Bấm nút tìm kiếm (kính lúp) ở thanh trên. | F39: Thanh tìm kiếm hiện với ô Find và ô Replace; bàn phím bật. | H39: Pass
A40: E05-02 | E40: Gõ từ cần tìm, bấm tìm trên bàn phím. | F40: Kết quả đầu tiên được tô sáng và cuộn vào giữa màn hình; có bộ đếm kiểu "1/7". | H40: Pass
...

Sheet Office_Chung
A1: ID | B1: Nhóm | C1: Tên test case | D1: Loại | E1: Ưu tiên | F1: Tiền điều kiện | G1: Các bước | H1: Kết quả mong đợi | I1: Ghi chú (từ phân tích code) | J1: Kết quả | K1: Thực tế / ghi chú của tester | L1: Thiết bị / bản build
A2: GEN-001 | B2: Mở file | C2: Mở file .docx từ tab Files | D2: Chức năng | E2: Cao | F2: Đã cấp quyền bộ nhớ; có F01 | G2: 1. Vào tab Files 2. Chạm file F01 | H2: Mở ở chế độ xem. Thanh trên: nút Back, icon Word, tên file, nút tìm kiếm, Share, More (⋮). Có nút Edit nổi. Nhãn "Page 1 / N". Không có màn xám. | J2: Pass
A3: GEN-002 | B3: Mở file | C3: Mở file .xlsx | D3: Chức năng | E3: Cao | F3: Có F04 | G3: 1. Chạm file F04 trong Files | H3: Mở ở chế độ xem. Nhãn "Sheet 1 / N". KHÔNG có nút tìm kiếm. Có nút Edit. | I3: Nút tìm kiếm chỉ có với Word sửa được. | J3: Pass
A4: GEN-003 | B4: Mở file | C4: Mở file .pptx | D4: Chức năng | E4: Cao | F4: Có F07 | G4: 1. Chạm file F07 trong Files | H4: Mở ở chế độ xem. Nhãn "Slide 1 / N". Có nút Play (trình chiếu) và nút Edit. | J4: Pass
A5: GEN-004 | B5: Mở file | C5: Mở file định dạng cũ .doc / .xls / .ppt | D5: Chức năng | E5: Cao | F5: Có F03, F06, F09 | G5: 1. Lần lượt mở F03, F06, F09 | H5: Có banner "Old .doc files are view-only." (đúng đuôi từng file). KHÔNG có nút Edit, KHÔNG có nút tìm kiếm. Nội dung hiển thị bình thường. | I5: SDK không chuyển đổi được định dạng cũ. | J5: Pass
A6: GEN-005 | B6: Mở file | C6: Mở file .xlsm | D6: Chức năng | E6: TB | F6: Có F05 | G6: 1. Mở F05 2. Bấm Edit | H6: Mở được, vào được chế độ sửa như .xlsx. | J6: Pass
A7: GEN-006 | B7: Mở file | C7: Mở từ màn Search | D7: Chức năng | E7: TB | F7: Có F01 | G7: 1. Bấm Search ở Files 2. Gõ tên F01 3. Chạm kết quả | H7: Mở đúng file; Back quay lại màn Search với từ khoá còn nguyên. | J7: Pass
A8: GEN-007 | B8: Mở file | C8: Mở bằng "Open a file" khi chưa cấp quyền bộ nhớ | D8: Chức năng | E8: Cao | F8: Chưa cấp quyền bộ nhớ | G8: 1. Ở tab Files bấm "Open a file" 2. Chọn 1 file .docx trong trình chọn hệ thống 3. Mở menu More (⋮) | H8: File mở được (bản sao trong app). Menu More KHÔNG có Favorite / File info / Delete; vẫn có Go to, Convert to PDF, Open with. | I8: Favorite/Info/Delete chỉ hiện khi file nằm trong thư viện đã quét. | J8: Pass
A9: GEN-008 | B9: Mở file | C9: Mở từ app khác (ACTION_VIEW) | D9: Chức năng | E9: Cao | F9: Có file Office trong trình quản lý file / Zalo / Gmail | G9: 1. Ở app khác chạm file .docx/.xlsx/.pptx 2. Chọn mở bằng app này 3. Bấm Back | H9: App mở thẳng vào màn đọc (không qua Main). Back quay về app đã gọi. | J9: Pass
A10: GEN-009 | B10: Mở file | C10: Mở từ app khác khi chưa qua first-run | D10: Biên | E10: TB | F10: Cài mới, chưa mở app lần nào | G10: 1. Từ trình quản lý file mở 1 file .pptx bằng app | H10: App đi qua các màn first-run rồi mở đúng file đã chọn; không crash, không mất file. | I10: PendingLaunch giữ file trong lúc chạy first-run. | J10: Pass
A11: GEN-010 | B11: Mở file | C11: File vừa mở xuất hiện trong Recent | D11: Chức năng | E11: TB | G11: 1. Mở F01 rồi Back 2. Xem tab/bộ lọc Recent | H11: F01 nằm đầu danh sách Recent. | J11: Fail | K11: Chưa có recnt view cho tài liêuh
A12: GEN-011 | B12: Mở file | C12: Mở từ màn Success (kết quả tool) | D12: Chức năng | E12: Thấp | F12: Vừa tạo file bằng 1 tool cho ra file Office (nếu có) | G12: 1. Ở màn Success bấm Open | H12: File Office mở trong màn Office; PDF mở trong màn PDF. | J12: Pass
A13: GEN-012 | B13: Lỗi khi mở | C13: File hỏng | D13: Chức năng | E13: Cao | F13: Có F12 (file .txt đổi đuôi thành .docx) | G13: 1. Mở F12 | H13: Dialog "Can’t open file" + "This file is damaged or is not a valid document." Bấm "Got it" → màn đóng. Không crash. | J13: Pass
A14: GEN-013 | B14: Lỗi khi mở | C14: File 0 byte | D14: Biên | E14: TB | F14: Có F13 | G14: 1. Mở F13 | H14: Hiện dialog "Can’t open file" (nội dung lỗi hỏng hoặc lỗi chung), đóng dialog thì màn đóng. Không crash, không treo loading. | J14: Pass
A15: GEN-014 | B15: Lỗi khi mở | C15: File đã bị xoá bên ngoài | D15: Biên | E15: TB | F15: Mở app, để ở danh sách Files | G15: 1. Dùng app khác xoá file F02 2. Quay lại app (không refresh), chạm F02 | H15: Dialog "Can’t open file" + "This file cannot be found or read. Check that it is still available." Màn đóng sau khi bấm Got it. | J15: Pass
A16: GEN-015 | B16: Lỗi khi mở | C16: File rất lớn | D16: Biên | E16: TB | F16: Có F14 (> 20 MB) | G16: 1. Mở F14 2. Chờ tới khi xong | H16: Mở được, hoặc dialog "There is not enough memory to open this document." Không crash, không ANR. | J16: Pass
A17: GEN-016 | B17: Lỗi khi mở | C17: Back khi đang loading | D17: Biên | E17: TB | F17: Có F02 (dài) | G17: 1. Mở F02 2. Bấm Back ngay khi vòng loading còn quay | H17: Thoát về danh sách ngay, không crash, không toast/dialog lỗi hiện muộn. | J17: Pass
A18: GEN-017 | B18: Lỗi khi mở | C18: Mở liên tiếp nhiều file | D18: Biên | E18: Thấp | G18: 1. Mở/đóng lần lượt 10 file Word, Excel, PowerPoint | H18: Không crash, không chậm dần, mỗi file hiện đúng nội dung của nó. | J18: Pass
A19: GEN-018 | B19: Mật khẩu | C19: File có mật khẩu → hỏi mật khẩu | D19: Chức năng | E19: Cao | F19: Có F10/F11 (đặt mật khẩu bằng MS Office) | G19: 1. Mở F10 | H19: Hiện dialog nhập mật khẩu, chưa hiện nội dung. | J19: Pass
A20: GEN-019 | B20: Mật khẩu | C20: Nhập sai mật khẩu | D20: Chức năng | E20: Cao | F20: Như trên | G20: 1. Nhập mật khẩu sai 2. Xác nhận | H20: Dialog hiện lại kèm báo mật khẩu sai; không crash; không đóng màn. | J20: Pass
A21: GEN-020 | B21: Mật khẩu | C21: Nhập đúng mật khẩu | D21: Chức năng | E21: Cao | F21: Như trên | G21: 1. Nhập mật khẩu đúng | H21: Tài liệu mở bình thường. | J21: Pass
A22: GEN-021 | B22: Mật khẩu | C22: Huỷ dialog mật khẩu | D22: Chức năng | E22: TB | F22: Như trên | G22: 1. Bấm Cancel hoặc Back ở dialog | H22: Màn Office đóng, quay về danh sách. | J22: Pass
A23: GEN-022 | B23: Mật khẩu | C23: Sửa và lưu file có mật khẩu | D23: Cần xác nhận | E23: TB | F23: Đã mở F10 bằng mật khẩu đúng | G23: 1. Bấm Edit (nếu có) 2. Sửa 1 chữ, Save 3. Đóng, mở lại file | H23: Ghi lại hành vi thực tế: có cho sửa không; sau khi lưu file còn hỏi mật khẩu không; nội dung còn đúng không. Không được hỏng file. | I23: Chưa xác định được từ code SDK có giữ mã hoá khi lưu hay không. | J23: Pass
A24: GEN-023 | B24: Menu More | C24: Các mục theo loại tài liệu | D24: Chức năng | E24: Cao | F24: Mở lần lượt F02, F04, F07 (đều trong thư viện) | G24: 1. Bấm More (⋮) ở mỗi file | H24: Word: Go to page, Convert to PDF, Open with, Favorite, File info, Delete. Excel: Go to sheet (khi > 1 sheet), Open with, Favorite, File info, Delete — KHÔNG có Convert to PDF. PowerPoint: Slideshow, Go to slide, Convert to PDF, Open with, Favorite, File info, Delete. | I24: Go to chỉ hiện khi tài liệu có > 1 trang/sheet/slide. | J24: Fail | K24: Không có tính năng go to page
A25: GEN-024 | B25: Menu More | C25: Go to — số hợp lệ | D25: Chức năng | E25: Cao | F25: Mở F02 | G25: 1. More → Go to page 2. Nhập 5 3. Done | H25: Nhảy tới trang 5, nhãn "Page 5 / N". Ô nhập mở ra có sẵn số trang hiện tại. | J25: Fail | K25: Không có tính năng go to page
A26: GEN-025 | B26: Menu More | C26: Go to — giá trị không hợp lệ | D26: Biên | E26: TB | F26: Mở F02 (N trang) | G26: 1. Go to page, lần lượt nhập: 0, N+1, -1, abc, để trống, 99999999999 | H26: Mỗi lần đều toast "Enter a number from 1 to N"; vị trí trang không đổi; không crash. | J26: Fail | K26: Không có tính năng go to page
A27: GEN-026 | B27: Menu More | C27: Go to — trang đầu và trang cuối | D27: Biên | E27: TB | F27: Mở F07 | G27: 1. Go to slide 1 2. Go to slide N | H27: Tới đúng slide đầu/cuối, nhãn đúng. | J27: Fail | K27: Không có tính năng go to page
A28: GEN-027 | B28: Menu More | C28: Favorite | D28: Chức năng | E28: TB | F28: Mở F01 | G28: 1. More → Favorite 2. Back, xem danh sách Favorite 3. Mở lại, More → bỏ Favorite | H28: File xuất hiện / biến mất khỏi Favorite tương ứng; nhãn mục trong menu đổi theo trạng thái. | J28: Pass
A29: GEN-028 | B29: Menu More | C29: File info | D29: Chức năng | E29: Thấp | F29: Mở F01 | G29: 1. More → File info | H29: Sheet thông tin: tên, đường dẫn, dung lượng, ngày sửa… đúng với file. | J29: Pass
A30: GEN-029 | B30: Menu More | C30: Delete — xác nhận | D30: Chức năng | E30: Cao | F30: Mở 1 file bỏ đi được | G30: 1. More → Delete 2. Xác nhận | H30: Màn đóng, file không còn trong danh sách và không còn trong bộ nhớ máy. | J30: Pass
A31: GEN-030 | B31: Menu More | C31: Delete — huỷ | D31: Chức năng | E31: TB | G31: 1. More → Delete 2. Bấm huỷ | H31: File còn nguyên, vẫn ở màn đọc. | J31: Pass
A32: GEN-031 | B32: Menu More | C32: Open with | D32: Chức năng | E32: Thấp | G32: 1. More → Open with | H32: Hiện chooser của hệ thống. Nếu máy không có app nào mở được: toast "No app found to open this file". | J32: Pass
A33: GEN-032 | B33: Menu More | C33: Share ở chế độ xem | D33: Chức năng | E33: TB | G33: 1. Bấm nút Share ở thanh trên 2. Chọn 1 app (vd Gmail) | H33: Share sheet hệ thống hiện; app nhận được đúng file. | J33: Pass
A34: GEN-033 | B34: Convert to PDF | C34: Word → PDF | D34: Chức năng | E34: Cao | F34: Mở F02, chờ tải xong | G34: 1. More → Convert to PDF 2. Chờ 3. Mở file kết quả | H34: Chạy màn Processing → Success. PDF có đủ số trang như bản Word. Chữ trong PDF là ảnh (không chọn được). | I34: Mỗi trang được vẽ thành ảnh rồi ghép PDF. | J34: Pass
A35: GEN-034 | B35: Convert to PDF | C35: PowerPoint → PDF | D35: Chức năng | E35: Cao | F35: Mở F07 | G35: 1. More → Convert to PDF 2. Mở file kết quả | H35: PDF có số trang = số slide, đúng thứ tự. | J35: Fail | K35: Không có tính năng convert psdf
A36: GEN-035 | B36: Convert to PDF | C36: Convert khi tài liệu chưa dàn trang xong | D36: Biên | E36: TB | F36: Có F02 (≥ 20 trang) | G36: 1. Mở F02 2. Ngay lập tức More → Convert to PDF | H36: Hoặc convert thành công đủ trang, hoặc toast "The document is still loading. Try again in a moment."; thử lại sau vài giây thì thành công. Không ra PDF thiếu trang. | J36: Pass
A37: GEN-036 | B37: Convert to PDF | C37: Bấm Convert nhiều lần liên tiếp | D37: Biên | E37: Thấp | F37: Mở F02 | G37: 1. More → Convert to PDF, mở lại menu và bấm tiếp trong lúc đang chạy | H37: Chỉ chạy 1 lần convert, chỉ ra 1 file kết quả. | J37: Pass
A38: GEN-037 | B38: Convert to PDF | C38: Tool "Office to PDF" từ tab Tools | D38: Chức năng | E38: Cao | G38: 1. Tab Tools → Office to PDF 2. Chọn F01 3. Chờ | H38: File mở rồi tự convert → Success. Back từ Success KHÔNG quay lại màn Office. | J38: Pass
A39: GEN-038 | B39: Convert to PDF | C39: Tool "Office to PDF" với file Excel | D39: Cần xác nhận | E39: TB | G39: 1. Tab Tools → Office to PDF 2. Thử chọn F04 (nếu trình chọn cho phép) | H39: Nếu chọn được: toast "This file can’t be converted to PDF yet", không crash, không kẹt ở màn Office. Ghi lại hành vi thực tế. | I39: Excel không vẽ được thành ảnh trang; chưa rõ PickFile có lọc bỏ Excel không. | J39: Blocked | K39: Butg -> bấm mở -> file ngắn -> action quá nhanh
A40: GEN-039 | B40: Tạo tài liệu mới | C40: Giá trị mặc định | D40: Chức năng | E40: TB | G40: 1. Mở màn New document | H40: Tên mặc định "Untitled-<Tháng>-<ngày>" (vd Untitled-Oct-12), con trỏ ở cuối tên; loại Word được chọn; đuôi ".docx"; có dòng Save to hiển thị thư mục lưu. | J40: Pass
...

Sheet Office_Word
A1: ID | B1: Nhóm | C1: Tên test case | D1: Loại | E1: Ưu tiên | F1: Tiền điều kiện | G1: Các bước | H1: Kết quả mong đợi | I1: Ghi chú (từ phân tích code) | J1: Kết quả | K1: Thực tế / ghi chú của tester | L1: Thiết bị / bản build
A2: WD-001 | B2: Xem | C2: Trang hiển thị ngay, không màn xám | D2: Chức năng | E2: Cao | F2: Có F01, F02 | G2: 1. Mở từng file | H2: Trang giấy trắng hiện trên nền xám nhạt ngay sau khi tải; không bị màn xám trống. | I2: App có workaround cho lỗi SDK không vẽ trang Word.
A3: WD-002 | B3: Xem | C3: Nhãn trang khi cuộn | D3: Chức năng | E3: TB | F3: Mở F02 | G3: 1. Cuộn từ đầu đến cuối | H3: Nhãn "Page x / N" tăng dần đúng; N ổn định sau khi dàn trang xong. | I3: Số trang có thể tăng dần trong lúc SDK dàn trang.
A4: WD-003 | B4: Tìm kiếm | C4: Mở tìm kiếm từ chế độ xem | D4: Chức năng | E4: Cao | F4: Mở F02 ở chế độ xem | G4: 1. Bấm nút tìm kiếm | H4: Thanh Find hiện với ô Find, ô Replace, nút Next, Replace, Replace all, Close; bàn phím bật, con trỏ ở ô Find. | I4: Tìm kiếm chạy trên trình sửa: app tạm vào chế độ sửa.
A5: WD-004 | B5: Tìm kiếm | C5: Tìm thấy | D5: Chức năng | E5: Cao | F5: Thanh Find đang mở | G5: 1. Gõ 1 từ có trong tài liệu 2. Bấm Next / phím Search 3. Bấm Next nhiều lần | H5: Kết quả được tô và cuộn tới; bộ đếm dạng "1/5", "2/5"… quay vòng khi hết. Bàn phím ẩn sau khi tìm.
A6: WD-005 | B6: Tìm kiếm | C6: Không tìm thấy | D6: Chức năng | E6: TB | G6: 1. Gõ "zzzxqq" 2. Next | H6: Toast "No matches"; bộ đếm trống.
A7: WD-006 | B7: Tìm kiếm | C7: Ô Find rỗng | D7: Biên | E7: Thấp | G7: 1. Để trống, bấm Next, Replace, Replace all | H7: Không có gì xảy ra, không crash.
A8: WD-007 | B8: Tìm kiếm | C8: Replace từng cái | D8: Chức năng | E8: Cao | G8: 1. Find = từ A, Replace = từ B 2. Bấm Replace 2 lần | H8: Mỗi lần thay 1 kết quả và nhảy tới kết quả kế; bộ đếm giảm đúng.
A9: WD-008 | B9: Tìm kiếm | C9: Replace all | D9: Chức năng | E9: Cao | G9: 1. Find = từ A (xuất hiện k lần), Replace = từ B 2. Replace all | H9: Toast "Replaced k"; toàn bộ A thành B; bộ đếm xoá.
A10: WD-009 | B10: Tìm kiếm | C10: Replace bằng chuỗi rỗng | D10: Biên | E10: TB | G10: 1. Find = từ A, Replace để trống 2. Replace all | H10: A bị xoá khỏi tài liệu; toast đúng số lượng.
A11: WD-010 | B11: Tìm kiếm | C11: Tìm có dấu / hoa thường / ký tự đặc biệt | D11: Biên | E11: TB | F11: Tài liệu có chữ tiếng Việt | G11: 1. Tìm "việt", "VIỆT", "viet", "(a+b)", "100%" | H11: Không crash. Ghi lại: có phân biệt hoa/thường, có phân biệt dấu không.
A12: WD-011 | B12: Tìm kiếm | C12: Đóng Find khi không sửa gì (mở từ xem) | D12: Chức năng | E12: TB | F12: Mở Find từ chế độ xem, chỉ tìm | G12: 1. Bấm Close | H12: Quay về chế độ XEM, không hỏi lưu.
A13: WD-012 | B13: Tìm kiếm | C13: Đóng Find sau khi đã Replace (mở từ xem) | D13: Chức năng | E13: TB | F13: Mở Find từ chế độ xem, đã Replace | G13: 1. Bấm Close | H13: Ở lại chế độ SỬA với trạng thái "Not saved" (để người dùng lưu).
A14: WD-013 | B14: Tìm kiếm | C14: Find từ ribbon (tab Review) | D14: Chức năng | E14: TB | F14: Đang ở chế độ sửa | G14: 1. Tab Review → Find & replace 2. Close | H14: Thanh Find mở; Close quay về chế độ sửa.
A15: WD-014 | B15: Tìm kiếm | C15: Back hệ thống khi Find mở | D15: Chức năng | E15: Thấp | G15: 1. Bấm Back hệ thống | H15: Giống bấm Close.
A16: WD-015 | B16: Gõ chữ | C16: Đặt con trỏ và gõ | D16: Chức năng | E16: Cao | F16: Mở F01 ở chế độ sửa | G16: 1. Chạm giữa 1 đoạn 2. Gõ "abc" | H16: Con trỏ đúng vị trí chạm, chữ chèn vào đó, trạng thái "Not saved".
A17: WD-016 | B17: Gõ chữ | C17: Gõ tiếng Việt | D17: Chức năng | E17: Cao | F17: Bàn phím Telex/VNI (Gboard, Laban Key) | G17: 1. Gõ "Tiếng Việt có dấu, đường, ưu, nghiêng" | H17: Chữ có dấu đúng, không lặp ký tự, không mất ký tự khi gõ nhanh. | I17: Ca hay lỗi với trình soạn thảo tự viết.
A18: WD-017 | B18: Gõ chữ | C18: Enter, Backspace, xoá qua ranh giới đoạn | D18: Chức năng | E18: Cao | G18: 1. Enter giữa đoạn 2. Backspace ở đầu đoạn mới 3. Giữ Backspace xoá nhiều | H18: Tách/gộp đoạn đúng; không crash.
A19: WD-018 | B19: Gõ chữ | C19: Backspace ở đầu tài liệu / đầu text box / header / footer | D19: Biên | E19: TB | F19: Tài liệu có text box, header | G19: 1. Đặt con trỏ ở đầu từng vùng 2. Bấm Backspace nhiều lần | H19: Không crash; không xoá nội dung ngoài vùng. | I19: SDK có 1 bản sửa crash cho ca này.
A20: WD-019 | B20: Gõ chữ | C20: Gõ ở cuối trang → sang trang mới | D20: Chức năng | E20: TB | G20: 1. Gõ Enter liên tục ở cuối trang cuối | H20: Trang mới được tạo, số trang tăng, con trỏ luôn nằm trên ribbon/bàn phím.
A21: WD-020 | B21: Gõ chữ | C21: Bàn phím bật ở trang ≥ 2 | D21: Cần xác nhận | E21: Cao | F21: Mở F02, cuộn tới giữa trang 3 | G21: 1. Chạm để đặt con trỏ (bàn phím bật) | H21: Vẫn ở đúng vị trí vừa chạm ở trang 3; không nhảy về trang 2. | I21: Word dùng cùng thành phần danh sách trang với PowerPoint (lỗi PP-BUG). Trang Word cao nên ít khả năng dính, cần kiểm tra.
A22: WD-021 | B22: Gõ chữ | C22: Chọn văn bản | D22: Chức năng | E22: TB | G22: 1. Nhấn giữ 1 từ 2. Kéo tay nắm chọn 2 dòng | H22: Vùng chọn hiển thị rõ, tay nắm kéo được.
A23: WD-022 | B23: Tab Home | C23: Font | D23: Chức năng | E23: Cao | F23: Chọn 1 đoạn chữ | G23: 1. Chạm chip Font 2. Chọn 1 font trong danh sách | H23: Chữ đổi font; chip hiện tên font vừa chọn. Đóng danh sách không chọn → không đổi gì.
A24: WD-023 | B24: Tab Home | C24: Size | D24: Chức năng | E24: Cao | F24: Chọn 1 đoạn chữ | G24: 1. Chạm chip Size 2. Chọn 24 | H24: Chữ cỡ 24; chip hiện "24".
A25: WD-024 | B25: Tab Home | C25: Bold / Italic / Underline | D25: Chức năng | E25: Cao | F25: Chọn 1 đoạn chữ | G25: 1. Bấm B, I, U 2. Bấm lại để tắt 3. Đặt con trỏ vào chữ đậm | H25: Định dạng bật/tắt đúng; nút tương ứng sáng khi con trỏ/vùng chọn đang có định dạng đó.
A26: WD-025 | B26: Tab Home | C26: Sheet Format | D26: Chức năng | E26: Cao | F26: Chọn 1 đoạn chữ | G26: 1. Bấm nút Format (bảng màu) 2. Thử lần lượt: Bold, Italic, Underline, Strikethrough, Superscript, Subscript, 4 kiểu căn lề, Bullets, Numbering | H26: Bàn phím ẩn khi sheet mở. Mỗi lần chạm áp dụng ngay vào tài liệu; nút sáng theo trạng thái.
A27: WD-026 | B27: Tab Home | C27: Sheet Format — màu chữ và highlight | D27: Chức năng | E27: TB | F27: Sheet Format đang mở | G27: 1. Chạm lần lượt 7 màu chữ 2. Chạm các màu highlight 3. Chạm chấm trắng ở hàng highlight | H27: Chữ đổi màu; nền chữ được tô; chấm trắng BỎ highlight. | I27: Không có màu nào được đánh dấu là màu hiện tại (SDK không cho biết).
A28: WD-027 | B28: Tab Home | C28: Sheet Format — Font / Size / Line spacing | D28: Chức năng | E28: TB | F28: Sheet Format đang mở | G28: 1. Bấm Font, chọn 2. Bấm Size, chọn 3. Bấm Spacing, chọn | H28: Áp dụng đúng; nút Font/Size trong sheet hiện giá trị đã chọn.
A29: WD-028 | B29: Tab Home | C29: Text color / Highlight trên ribbon | D29: Chức năng | E29: TB | F29: Chọn chữ | G29: 1. Bấm Text color, chọn màu trong hộp thoại SDK 2. Bấm Highlight, chọn màu | H29: Áp dụng đúng; huỷ hộp thoại không đổi gì.
A30: WD-029 | B30: Tab Home | C30: Bullets / Numbering | D30: Chức năng | E30: TB | F30: Đặt con trỏ trong 3 đoạn liên tiếp (chọn cả 3) | G30: 1. Bấm Bullets 2. Bấm Numbering 3. Bấm lại để tắt | H30: Danh sách chấm / số 1-2-3 đúng; tắt được.
A31: WD-030 | B31: Tab Home | C31: Định dạng khi không chọn chữ | D31: Biên | E31: TB | F31: Chỉ có con trỏ, không chọn | G31: 1. Bấm B rồi gõ chữ | H31: Chữ gõ tiếp theo là chữ đậm (hoặc không đổi) — không crash. Ghi lại hành vi.
A32: WD-031 | B32: Tab Insert | C32: Chèn bảng | D32: Chức năng | E32: Cao | G32: 1. Tab Insert → Table 2. Chọn 3 × 4 trên lưới | H32: Bàn phím ẩn; bảng 3 hàng × 4 cột chèn tại con trỏ.
A33: WD-032 | B33: Tab Insert | C33: Huỷ chèn bảng | D33: Chức năng | E33: Thấp | G33: 1. Table → đóng sheet | H33: Không chèn gì.
A34: WD-033 | B34: Tab Insert | C34: Chèn ảnh từ thư viện | D34: Chức năng | E34: Cao | G34: 1. Insert → Picture 2. Chọn 1 ảnh | H34: Ảnh chèn tại con trỏ, tỷ lệ đúng.
A35: WD-034 | B35: Tab Insert | C35: Chèn ảnh rất lớn / ảnh HEIC / GIF | D35: Biên | E35: TB | F35: Có ảnh 12MP+, ảnh .heic | G35: 1. Chèn lần lượt | H35: Chèn được hoặc báo lỗi; không crash, không treo.
A36: WD-035 | B36: Tab Insert | C36: Chèn ảnh từ Camera | D36: Chức năng | E36: TB | G36: 1. Insert → Camera 2. Chụp, xác nhận | H36: Ảnh vừa chụp chèn vào tài liệu.
A37: WD-036 | B37: Tab Insert | C37: Camera — huỷ chụp / từ chối quyền | D37: Biên | E37: TB | G37: 1. Insert → Camera 2. Bấm Back ở camera | H37: Quay lại trình sửa, không chèn gì, không crash.
A38: WD-037 | B38: Tab Insert | C38: Insert text / New line | D38: Chức năng | E38: Thấp | G38: 1. Bấm Insert text, nhập, xác nhận 2. Bấm New line | H38: Chữ được chèn; xuống dòng mới.
A39: WD-038 | B39: Tab Layout | C39: Căn lề trái / giữa / phải / đều | D39: Chức năng | E39: Cao | F39: Con trỏ trong 1 đoạn dài | G39: 1. Bấm lần lượt 4 nút | H39: Đoạn căn đúng; nút đang áp dụng sáng.
A40: WD-039 | B40: Tab Layout | C40: Thụt lề | D40: Chức năng | E40: TB | G40: 1. Indent more ×3 2. Indent less ×5 | H40: Thụt vào/ra đúng; không âm quá lề.
...

Sheet Office_Excel
A1: ID | B1: Nhóm | C1: Tên test case | D1: Loại | E1: Ưu tiên | F1: Tiền điều kiện | G1: Các bước | H1: Kết quả mong đợi | I1: Ghi chú (từ phân tích code) | J1: Kết quả | K1: Thực tế / ghi chú của tester | L1: Thiết bị / bản build
A2: XL-001 | B2: Xem | C2: Chuyển sheet | D2: Chức năng | E2: Cao | F2: Mở F04 (≥ 3 sheet) | G2: 1. Chạm tab sheet 2, 3 2. More → Go to sheet → 1 | H2: Hiện đúng dữ liệu từng sheet; nhãn "Sheet x / N".
A3: XL-002 | B3: Xem | C3: Công thức hiển thị giá trị | D3: Chức năng | E3: Cao | F3: F04 có công thức | G3: 1. Xem các ô có SUM, AVERAGE, IF | H3: Ô hiện kết quả đúng (so với Excel trên máy tính).
A4: XL-003 | B4: Xem | C4: Cuộn / zoom bảng lớn | D4: Chức năng | E4: TB | F4: F04 có ≥ 1000 dòng | G4: 1. Cuộn dọc, ngang, zoom | H4: Tiêu đề hàng/cột đi theo; mượt; không trắng ô.
A5: XL-004 | B5: Ô công thức | C5: Hiện ô công thức khi sửa | D5: Chức năng | E5: Cao | F5: Mở F04 | G5: 1. Bấm Edit | H5: Thanh công thức hiện: nhãn ô (vd A1), ô nhập, nút ✓. Ribbon có tab Home, Insert, Cells, Sheet.
A6: XL-005 | B6: Ô công thức | C6: Chọn ô → hiện địa chỉ và nội dung | D6: Chức năng | E6: Cao | F6: Đang sửa | G6: 1. Chạm ô B2 có giá trị 2. Chạm ô có công thức | H6: Nhãn hiện "B2"; ô nhập hiện giá trị; với ô công thức hiện "=…".
A7: XL-006 | B7: Ô công thức | C7: Chọn vùng | D7: Chức năng | E7: TB | G7: 1. Kéo chọn B2 đến D4 | H7: Nhãn hiện "B2:D4".
A8: XL-007 | B8: Ô công thức | C8: Nhập số và chữ | D8: Chức năng | E8: Cao | F8: Chọn ô trống | G8: 1. Gõ 123, bấm ✓ 2. Chọn ô khác, gõ "Xin chào", bấm phím Done | H8: Ô nhận giá trị; bàn phím ẩn; ô nhập mất focus; trạng thái "Not saved".
A9: XL-008 | B9: Ô công thức | C9: Nhập công thức | D9: Chức năng | E9: Cao | F9: A1=1, A2=2, A3=3 | G9: 1. Chọn A4, gõ =SUM(A1:A3), ✓ 2. Đổi A1 thành 10 | H9: A4 hiện 6, sau đó 15 (tự tính lại).
A10: XL-009 | B10: Ô công thức | C10: Công thức sai / tham chiếu vòng | D10: Biên | E10: TB | G10: 1. Nhập =SUM(, =1/0, =A4 vào chính A4, =ABCXYZ(1) | H10: Không crash; ô hiện lỗi hoặc giữ chuỗi. Ghi lại hành vi.
A11: XL-010 | B11: Ô công thức | C11: Xoá nội dung ô | D11: Chức năng | E11: TB | F11: Chọn ô có giá trị | G11: 1. Xoá hết chữ trong ô nhập, ✓ | H11: Ô trống.
A12: XL-011 | B12: Ô công thức | C12: Đổi ô khi đang gõ dở | D12: Biên | E12: TB | F12: Đang gõ trong ô nhập (chưa ✓) | G12: 1. Chạm sang ô khác trên bảng | H12: Ghi lại: chữ đang gõ có bị mất / ghi vào ô nào. Không crash, không ghi nhầm ô. | I12: Ô nhập không bị ghi đè khi đang focus; cần xem giá trị dở được áp vào ô cũ hay ô mới.
A13: XL-012 | B13: Ô công thức | C13: Chuỗi dài / tiếng Việt / số âm / ngày | D13: Biên | E13: TB | G13: 1. Nhập chuỗi 500 ký tự, chữ có dấu, -12.5, 12/10/2026, 50% | H13: Lưu đúng giá trị; không crash.
A14: XL-013 | B14: Tab Home | C14: Bold / Italic / Underline | D14: Chức năng | E14: Cao | F14: Chọn vùng ô có chữ | G14: 1. Bấm B, I, U; bấm lại để tắt | H14: Định dạng áp dụng cho cả vùng; nút sáng theo ô đang chọn.
A15: XL-014 | B15: Tab Home | C15: Fill color / Text color | D15: Chức năng | E15: TB | F15: Chọn vùng | G15: 1. Fill color → chọn màu 2. Text color → chọn màu | H15: Nền và màu chữ ô đổi đúng.
A16: XL-015 | B16: Tab Home | C16: Sheet Cell format — áp dụng | D16: Chức năng | E16: Cao | F16: Chọn B2:D4 | G16: 1. Bấm nút Cell format 2. Chọn 1 màu nền, căn giữa, bật Wrap 3. Bấm "Apply to B2:D4" | H16: Nút Apply ghi đúng vùng đang chọn. Sau khi Apply: cả 3 thuộc tính áp vào vùng.
A17: XL-016 | B17: Tab Home | C17: Sheet Cell format — đóng không Apply | D17: Chức năng | E17: TB | G17: 1. Mở sheet, chọn màu + căn lề 2. Bấm X đóng | H17: Không có gì thay đổi trên bảng. | I17: Chỉ thay đổi khi bấm Apply.
A18: XL-017 | B18: Tab Home | C18: Sheet Cell format — màu trắng = bỏ nền | D18: Chức năng | E18: Thấp | F18: Ô đã có nền màu | G18: 1. Mở sheet, chọn chấm trắng, Apply | H18: Ô hết màu nền.
A19: XL-018 | B19: Tab Home | C19: Sheet Cell format — không có Number format | D19: Lỗi đã biết | E19: Thấp | G19: 1. Mở sheet Cell format | H19: KHÔNG có mục định dạng số (đã bỏ có chủ đích). | I19: Lệnh NUMBER_FORMAT của SDK luôn ném lỗi nên app chưa đưa vào.
A20: XL-019 | B20: Tab Home | C20: Căn trái / giữa / phải | D20: Chức năng | E20: TB | F20: Chọn vùng | G20: 1. Bấm 3 nút căn lề | H20: Áp dụng đúng.
A21: XL-020 | B21: Tab Home | C21: Merge cells | D21: Chức năng | E21: Cao | F21: Chọn B2:D2 | G21: 1. Bấm Merge 2. Chọn ô đã gộp, bấm Merge lần nữa | H21: Gộp thành 1 ô; lần 2 bỏ gộp.
A22: XL-021 | B22: Tab Home | C22: Font size | D22: Chức năng | E22: TB | F22: Chọn ô | G22: 1. Font size → chọn 18 | H22: Chữ to lên; chiều cao hàng phù hợp.
A23: XL-022 | B23: Tab Insert | C23: Chèn hàng / cột | D23: Chức năng | E23: Cao | F23: Chọn ô C5 | G23: 1. Row above, Row below, Column left, Column right | H23: Hàng/cột mới ở đúng phía; dữ liệu và CÔNG THỨC tham chiếu dịch đúng.
A24: XL-023 | B24: Tab Insert | C24: Chèn ảnh | D24: Chức năng | E24: TB | G24: 1. Insert → Picture → chọn ảnh | H24: Ảnh nằm trên sheet tại vùng ô đang chọn.
A25: XL-024 | B25: Tab Cells | C25: Row height / Column width | D25: Chức năng | E25: TB | F25: Chọn ô | G25: 1. Row height → nhập giá trị 2. Column width → nhập giá trị | H25: Kích thước đổi đúng; nhập 0 / số âm / chữ không crash.
A26: XL-025 | B26: Tab Cells | C26: Wrap text | D26: Chức năng | E26: TB | F26: Ô có chuỗi dài | G26: 1. Bấm Wrap text; bấm lại | H26: Chữ xuống dòng trong ô / trở lại 1 dòng.
A27: XL-026 | B27: Tab Cells | C27: Borders | D27: Chức năng | E27: TB | F27: Chọn vùng | G27: 1. Borders → chọn kiểu viền | H27: Viền hiển thị đúng kiểu chọn. | I27: Hộp thoại do SDK hiển thị.
A28: XL-027 | B28: Tab Cells | C28: Text rotation / Cell alignment | D28: Chức năng | E28: Thấp | F28: Chọn ô có chữ | G28: 1. Text rotation → chọn góc 2. Cell alignment → chọn dọc giữa | H28: Chữ xoay / căn dọc đúng.
A29: XL-028 | B29: Tab Cells | C29: Delete row / Delete column | D29: Chức năng | E29: Cao | F29: Chọn ô | G29: 1. Delete row 2. Delete column | H29: Xoá đúng hàng/cột; công thức liên quan cập nhật hoặc báo lỗi tham chiếu, không crash.
A30: XL-029 | B30: Tab Cells | C30: Clear cells | D30: Chức năng | E30: TB | F30: Chọn vùng có dữ liệu | G30: 1. Bấm Clear cells | H30: Nội dung vùng bị xoá; Undo khôi phục.
A31: XL-030 | B31: Tab Sheet | C31: Add sheet | D31: Chức năng | E31: Cao | G31: 1. Tab Sheet → Add sheet | H31: Sheet mới được thêm; nhãn tổng số sheet tăng 1.
A32: XL-031 | B32: Tab Sheet | C32: Go to cell | D32: Chức năng | E32: TB | G32: 1. Go to cell → nhập C10 2. Nhập ZZ99999, nhập abc, để trống | H32: Nhảy tới C10 và chọn ô đó. Giá trị sai: không crash, có thông báo hoặc bỏ qua.
A33: XL-032 | B33: Tổng hợp | C33: Undo / Redo | D33: Chức năng | E33: Cao | G33: 1. Nhập giá trị, tô màu, chèn hàng, gộp ô 2. Undo 4 lần, Redo 4 lần | H33: Lùi/tiến đúng từng bước.
A34: XL-033 | B34: Tổng hợp | C34: Lưu và mở lại | D34: Chức năng | E34: Cao | F34: Đã sửa ở 2 sheet khác nhau | G34: 1. Save 2. Đóng app, mở lại file | H34: Thay đổi ở cả 2 sheet còn đủ; sheet không sửa không bị ảnh hưởng.
A35: XL-034 | B35: Tổng hợp | C35: Mở file đã lưu bằng MS Excel / Google Sheets | D35: Chức năng | E35: Cao | F35: File vừa lưu | G35: 1. Mở trên máy tính | H35: Không báo hỏng; giá trị, công thức, định dạng khớp.
A36: XL-035 | B36: Tổng hợp | C36: Lưu file .xlsm | D36: Cần xác nhận | E36: TB | F36: Mở F05 (có macro) | G36: 1. Sửa 1 ô, Save 2. Mở lại bằng Excel trên máy tính | H36: File mở được; ghi lại macro còn hay mất. | I36: Chưa xác định từ code SDK có giữ macro khi ghi.
A37: XL-036 | B37: Tổng hợp | C37: Excel mới tạo: nhập bảng → công thức → lưu | D37: Chức năng | E37: Cao | F37: Tạo Excel mới | G37: 1. Nhập bảng 5×3, thêm hàng tổng bằng SUM, tô tiêu đề 2. Save, mở lại | H37: Đúng dữ liệu, công thức và định dạng.
A38: XL-037 | B38: Tổng hợp | C38: Không có Convert to PDF và không có nút tìm kiếm | D38: Chức năng | E38: TB | F38: Mở F04 | G38: 1. Xem thanh trên và menu More | H38: Không có 2 mục này (giới hạn hiện tại).
A39: XL-038 | B39: Tổng hợp | C39: Bàn phím che ô đang sửa | D39: Biên | E39: TB | F39: Chọn ô ở cuối màn hình | G39: 1. Chạm ô nhập công thức | H39: Ribbon + ô công thức nằm trên bàn phím; ô đang chọn vẫn thấy được hoặc cuộn tới được.

Sheet Office_PowerPoint
A1: ID | B1: Nhóm | C1: Tên test case | D1: Loại | E1: Ưu tiên | F1: Tiền điều kiện | G1: Các bước | H1: Kết quả mong đợi | I1: Ghi chú (từ phân tích code) | J1: Kết quả | K1: Thực tế / ghi chú của tester | L1: Thiết bị / bản build
A2: PP-001 | B2: Xem | C2: Cuộn giữa các slide | D2: Chức năng | E2: Cao | F2: Mở F07 (≥ 5 slide) | G2: 1. Vuốt dọc qua từng slide | H2: Mỗi lần vuốt sang 1 slide; nhãn "Slide x / N" đúng.
A3: PP-002 | B3: Dải slide | C3: Hiện dải thumbnail khi sửa | D3: Chức năng | E3: Cao | F3: Mở F07 | G3: 1. Bấm Edit | H3: Dải thumbnail slide hiện phía trên ribbon; slide hiện tại được đánh dấu; có nút Arrange. Ribbon có tab Home, Insert, Animations, Slideshow.
A4: PP-003 | B4: Dải slide | C4: Chạm thumbnail để chuyển slide | D4: Chức năng | E4: Cao | F4: Đang sửa | G4: 1. Chạm thumbnail 4 2. Chạm thumbnail 1 | H4: Vùng chính chuyển tới đúng slide; thumbnail đó được đánh dấu.
A5: PP-004 | B5: Dải slide | C5: Dải slide theo khi cuộn vùng chính | D5: Chức năng | E5: TB | G5: 1. Vuốt vùng chính tới slide cuối | H5: Thumbnail đánh dấu đổi theo và tự cuộn vào tầm nhìn.
A6: PP-005 | B6: Chọn shape | C6: Chọn và bỏ chọn | D6: Chức năng | E6: Cao | F6: Slide có vài shape | G6: 1. Chạm 1 shape 2. Chạm vùng trống | H6: Khung chọn có tay nắm bao quanh shape; chạm vùng trống thì bỏ chọn.
A7: PP-006 | B7: Chọn shape | C7: Di chuyển / đổi kích thước / xoay bằng tay | D7: Chức năng | E7: Cao | F7: Đã chọn 1 shape | G7: 1. Kéo shape 2. Kéo tay nắm góc 3. Kéo tay nắm xoay (nếu có) | H7: Shape theo ngón tay; thả ra giữ vị trí mới; thumbnail cập nhật; trạng thái "Not saved".
A8: PP-007 | B8: Chọn shape | C8: Ảnh giữ tỷ lệ khi resize | D8: Chức năng | E8: Thấp | F8: Đã chọn 1 ảnh | G8: 1. Kéo tay nắm góc | H8: Ảnh không méo.
A9: PP-008 | B9: Chọn shape | C9: Chọn shape chồng nhau | D9: Biên | E9: TB | F9: 2 shape đè lên nhau | G9: 1. Chạm vùng giao nhau | H9: Chọn shape ở lớp trên.
A10: PP-009 | B10: Sửa chữ tại chỗ | C10: Mở ô nhập bằng chạm lần 2 — slide 1 (đối chứng) | D10: Chức năng | E10: Cao | F10: Slide 1 có text box | G10: 1. Chạm text box (chọn) 2. Chạm lần nữa | H10: Ô nhập mở ngay trên shape với chữ hiện có, bàn phím bật, ribbon ẩn. Vẫn ở slide 1. | I10: Ở slide 1 không bị lỗi nhảy slide.
A11: PP-010 | B11: Sửa chữ tại chỗ | C11: Gõ và kết thúc nhập | D11: Chức năng | E11: Cao | F11: Ô nhập đang mở | G11: 1. Gõ "Tiêu đề mới" 2. Chạm ra ngoài shape | H11: Ô nhập đóng, bàn phím ẩn, ribbon hiện lại. Chữ mới hiển thị trên slide và trên thumbnail.
A12: PP-011 | B12: Sửa chữ tại chỗ | C12: Gõ tiếng Việt, nhiều dòng | D12: Chức năng | E12: TB | F12: Ô nhập đang mở | G12: 1. Gõ 3 dòng chữ có dấu | H12: Chữ đúng dấu; xuống dòng được; lưu đúng 3 dòng.
A13: PP-012 | B13: Sửa chữ tại chỗ | C13: Định dạng một phần chữ | D13: Chức năng | E13: TB | F13: Ô nhập đang mở | G13: 1. Nhấn giữ chọn 1 từ 2. Trong menu chọn Bold / Italic / Underline / Red text | H13: Chỉ từ đó đổi định dạng; ô nhập đóng và slide vẽ lại đúng.
A14: PP-013 | B14: Sửa chữ tại chỗ | C14: Xoá hết chữ | D14: Biên | E14: TB | G14: 1. Xoá toàn bộ chữ trong ô nhập 2. Chạm ra ngoài | H14: Shape còn nhưng rỗng (hoặc giữ chữ cũ) — không crash. Ghi lại hành vi.
A15: PP-014 | B15: Sửa chữ tại chỗ | C15: Text box sát đáy slide | D15: Biên | E15: TB | F15: Kéo text box xuống đáy slide | G15: 1. Chạm 2 lần để nhập | H15: Ô nhập hiện phía trên bàn phím, không bị che.
A16: PP-015 | B16: Sửa chữ tại chỗ | C16: Đóng bàn phím bằng Back khi đang nhập | D16: Biên | E16: TB | F16: Ô nhập đang mở, đã gõ chữ | G16: 1. Bấm Back hệ thống 1 lần | H16: Ghi lại: chỉ đóng bàn phím hay thoát luôn nhập; chữ đã gõ không được mất âm thầm.
A17: PP-016 | B17: Lỗi nhảy slide | C17: Nhập chữ vào text box ở slide 2 (lỗi đã báo) | D17: Lỗi đã biết | E17: Cao | F17: Tạo PowerPoint mới | G17: 1. Tab Insert → Add slide (đang ở slide 2) 2. Insert → Text box 3. Chạm lần nữa vào text box để nhập | H17: MONG ĐỢI: vẫn ở slide 2, ô nhập mở trên text box. HIỆN TẠI (lỗi): màn hình nhảy về slide 1. | I17: Lỗi trong SDK (APageListView.layoutVertical): khi bàn phím che hơn nửa vùng tài liệu, danh sách slide tự lùi 1 slide.
A18: PP-017 | B18: Lỗi nhảy slide | C18: Slide 3 trong bộ 5 slide | D18: Lỗi đã biết | E18: Cao | F18: Mở F07, vào sửa | G18: 1. Chạm thumbnail 3 2. Chọn 1 text box, chạm lần nữa | H18: MONG ĐỢI: vẫn ở slide 3. HIỆN TẠI (dự đoán): nhảy về slide 2. | I18: Cùng nguyên nhân: lùi đúng 1 slide.
A19: PP-018 | B19: Lỗi nhảy slide | C19: Slide cuối | D19: Lỗi đã biết | E19: TB | F19: Mở F07, vào sửa | G19: 1. Tới slide cuối 2. Chạm 2 lần vào text box | H19: MONG ĐỢI: vẫn ở slide cuối. HIỆN TẠI (dự đoán): nhảy về slide áp cuối.
A20: PP-019 | B20: Lỗi nhảy slide | C20: Chữ gõ sau khi bị nhảy có vào đúng slide không | D20: Lỗi đã biết | E20: Cao | F20: Vừa tái hiện ca slide 2; slide 1 cũng có text box | G20: 1. Sau khi bị nhảy, gõ "ABC" 2. Chạm ra ngoài để kết thúc 3. Xem slide 1 và slide 2 | H20: MONG ĐỢI: "ABC" nằm trong text box của slide 2; slide 1 không đổi. RỦI RO: báo lỗi không đổi được chữ, hoặc chữ ghi nhầm vào shape ở slide 1. | I20: SDK lấy slide hiện tại lúc ghi chữ; sau khi nhảy slide hiện tại đã là slide 1.
A21: PP-020 | B21: Lỗi nhảy slide | C21: Lệnh Set text ở slide ≥ 2 | D21: Cần xác nhận | E21: Cao | F21: Ở slide 2, đã chọn text box | G21: 1. Tab Home → Set text 2. Gõ chữ trong hộp thoại, OK | H21: Vẫn ở slide 2; chữ đổi đúng ở slide 2. | I21: Hộp thoại cũng bật bàn phím, có thể gây cùng lỗi nhảy slide.
A22: PP-021 | B22: Lỗi nhảy slide | C22: Bàn phím nổi / bàn phím thấp | D22: Cần xác nhận | E22: TB | F22: Bật chế độ bàn phím nổi (Gboard floating) | G22: 1. Lặp lại ca slide 2 | H22: Vẫn ở slide 2 (bàn phím không che nửa vùng tài liệu nên dự đoán KHÔNG lỗi). | I22: Dùng để khẳng định điều kiện gây lỗi.
A23: PP-022 | B23: Lỗi nhảy slide | C23: Sau khi bị nhảy: thumbnail và nhãn | D23: Lỗi đã biết | E23: TB | F23: Vừa tái hiện lỗi | G23: 1. Quan sát dải thumbnail | H23: Ghi lại thumbnail đang đánh dấu slide nào và ô nhập đang nằm ở đâu (lệch slide).
A24: PP-023 | B24: Tab Home | C24: Lệnh định dạng khi chưa chọn shape | D24: Biên | E24: TB | F24: Không chọn shape nào | G24: 1. Bấm B, I, U, Text color, Size, căn lề, Set text, Rotate, Delete | H24: Mỗi lệnh hiện thông báo yêu cầu chọn shape trước; không crash; trạng thái vẫn "Saved". | I24: Thông báo do SDK hiển thị.
A25: PP-024 | B25: Tab Home | C25: Bold / Italic / Underline cho cả shape | D25: Chức năng | E25: Cao | F25: Chọn 1 text box | G25: 1. Bấm B, I, U; bấm lại | H25: Toàn bộ chữ trong shape đổi; nút sáng theo trạng thái; bấm lại thì tắt.
A26: PP-025 | B26: Tab Home | C26: Size | D26: Chức năng | E26: TB | F26: Chọn 1 text box | G26: 1. Chạm chip Size, chọn 40 | H26: Chữ cỡ 40; chip hiện "40".
A27: PP-026 | B27: Tab Home | C27: Text color | D27: Chức năng | E27: TB | F27: Chọn 1 text box | G27: 1. Text color → chọn màu | H27: Chữ đổi màu; huỷ hộp thoại không đổi.
A28: PP-027 | B28: Tab Home | C28: Căn trái / giữa / phải | D28: Chức năng | E28: TB | F28: Chọn 1 text box | G28: 1. Bấm 3 nút | H28: Chữ căn đúng trong shape.
A29: PP-028 | B29: Tab Home | C29: Set text | D29: Chức năng | E29: TB | F29: Chọn 1 text box (ở slide 1) | G29: 1. Set text → sửa chữ → OK 2. Set text → Cancel | H29: OK: chữ đổi. Cancel: giữ nguyên.
A30: PP-029 | B30: Tab Home | C30: Rotate | D30: Chức năng | E30: TB | F30: Chọn 1 shape | G30: 1. Bấm Rotate 4 lần | H30: Mỗi lần xoay thêm 90°, sau 4 lần về như cũ; khung chọn xoay theo.
A31: PP-030 | B31: Tab Home | C31: Shape list | D31: Chức năng | E31: TB | F31: Slide có ≥ 3 shape | G31: 1. Bấm Shape list 2. Chạm 1 dòng để chọn 3. Đổi thứ tự lớp lên/xuống | H31: Danh sách đúng các shape của slide; chọn được; shape chồng nhau đổi lớp đúng.
A32: PP-031 | B32: Tab Home | C32: Shape list ở slide trống | D32: Biên | E32: Thấp | F32: Slide không có shape | G32: 1. Bấm Shape list | H32: Thông báo slide không có shape; không crash.
A33: PP-032 | B33: Tab Home | C33: Delete shape | D33: Chức năng | E33: Cao | F33: Chọn 1 shape | G33: 1. Bấm Delete (đỏ) 2. Undo | H33: Shape biến mất, khung chọn mất; Undo khôi phục.
A34: PP-033 | B34: Tab Home | C34: Delete khi đang nhập chữ | D34: Biên | E34: TB | F34: Ô nhập đang mở | G34: 1. Bấm Delete | H34: Shape bị xoá, ô nhập đóng; không crash.
A35: PP-034 | B35: Tab Insert | C35: Text box | D35: Chức năng | E35: Cao | G35: 1. Insert → Text box | H35: Text box chữ "Text box" xuất hiện giữa slide HIỆN TẠI, đang được chọn; thumbnail cập nhật.
A36: PP-035 | B36: Tab Insert | C36: Picture | D36: Chức năng | E36: Cao | G36: 1. Insert → Picture → chọn ảnh | H36: Ảnh giữa slide, rộng tối đa nửa slide, đúng tỷ lệ, đang được chọn.
A37: PP-036 | B37: Tab Insert | C37: Picture — ảnh hỏng / huỷ chọn | D37: Biên | E37: TB | G37: 1. Huỷ trình chọn ảnh 2. Chọn 1 file ảnh hỏng | H37: Không thêm gì; có thông báo với ảnh hỏng; không crash.
A38: PP-037 | B38: Tab Insert | C38: Shape | D38: Chức năng | E38: Cao | G38: 1. Insert → Shape 2. Chọn loại và màu | H38: Shape đúng loại, màu, ở giữa slide, đang được chọn. Huỷ hộp thoại thì không thêm.
A39: PP-038 | B39: Tab Insert | C39: Add slide | D39: Chức năng | E39: Cao | F39: Đang ở slide k của N | G39: 1. Insert → Add slide | H39: Slide trống mới ở vị trí k+1; màn hình chuyển sang slide mới; dải thumbnail có N+1 slide; nhãn "Slide k+1 / N+1". | I39: Tài liệu được tải lại từ bản sao làm việc sau thao tác slide.
A40: PP-039 | B40: Tab Insert | C40: Duplicate slide | D40: Chức năng | E40: Cao | F40: Đang ở slide k | G40: 1. Insert → Duplicate slide | H40: Bản sao ở vị trí k+1 và được hiển thị; nội dung giống slide k.
...

Sheet Office_Slideshow
A1: ID | B1: Nhóm | C1: Tên test case | D1: Loại | E1: Ưu tiên | F1: Tiền điều kiện | G1: Các bước | H1: Kết quả mong đợi | I1: Ghi chú (từ phân tích code) | J1: Kết quả | K1: Thực tế / ghi chú của tester | L1: Thiết bị / bản build
A2: SS-001 | B2: Bắt đầu | C2: Từ nút Play ở chế độ xem | D2: Chức năng | E2: Cao | F2: Mở F07, đang ở slide 3 | G2: 1. Bấm Play | H2: Màn hình xoay ngang, nền tối, hiện slide 3 toàn màn hình, nhãn "3 / N"; có nút Exit, Previous, Next, Pen, Eraser.
A3: SS-002 | B3: Bắt đầu | C3: Từ menu More → Slideshow | D3: Chức năng | E3: TB | G3: 1. More → Slideshow | H3: Như trên.
A4: SS-003 | B4: Bắt đầu | C4: Từ nút Play trên thanh sửa | D4: Chức năng | E4: TB | F4: Đang ở chế độ sửa | G4: 1. Bấm Play | H4: Như trên; bàn phím (nếu đang mở) ẩn.
A5: SS-004 | B5: Bắt đầu | C5: Từ ribbon tab Slideshow | D5: Chức năng | E5: TB | F5: Đang ở chế độ sửa | G5: 1. Tab Slideshow → Slideshow | H5: Như trên.
A6: SS-005 | B6: Bắt đầu | C6: Bắt đầu khi tài liệu chưa sẵn sàng | D6: Biên | E6: Thấp | G6: 1. Mở F08 (nặng) và bấm Play ngay | H6: Trình chiếu được, hoặc toast "The slideshow isn’t ready yet"; không crash.
A7: SS-006 | B7: Bắt đầu | C7: Trình chiếu bản đang sửa chưa lưu | D7: Chức năng | E7: Cao | F7: Đã sửa chữ + thêm slide, chưa Save | G7: 1. Bấm Play | H7: Slide hiển thị nội dung MỚI (bản đang sửa), có cả slide vừa thêm.
A8: SS-007 | B8: Bắt đầu | C8: Bấm Play khi đang nhập chữ tại chỗ | D8: Cần xác nhận | E8: TB | F8: Ô nhập trên text box đang mở, đã gõ chữ | G8: 1. Bấm Play | H8: Bàn phím ẩn; trình chiếu hiện đúng. Sau khi thoát: chữ đang gõ không mất. Ghi lại hành vi.
A9: SS-008 | B9: Điều hướng | C9: Next bằng nút và bằng chạm slide | D9: Chức năng | E9: Cao | F9: Đang trình chiếu | G9: 1. Bấm Next 2. Chạm vào slide | H9: Mỗi lần sang 1 slide; nhãn tăng.
A10: SS-009 | B10: Điều hướng | C10: Previous | D10: Chức năng | E10: Cao | G10: 1. Bấm Previous | H10: Lùi 1 slide.
A11: SS-010 | B11: Điều hướng | C11: Giới hạn đầu / cuối | D11: Biên | E11: TB | G11: 1. Ở slide 1 bấm Previous 2. Ở slide cuối bấm Next / chạm slide | H11: Không đổi slide, không crash, không thoát trình chiếu.
A12: SS-011 | B12: Điều hướng | C12: Bấm Next rất nhanh qua 20+ slide | D12: Biên | E12: TB | F12: Bộ ≥ 20 slide | G12: 1. Bấm Next liên tục | H12: Slide cuối cùng hiển thị khớp với nhãn (không bị ảnh slide cũ đến muộn đè lên).
A13: SS-012 | B13: Điều hướng | C13: Bộ chỉ có 1 slide | D13: Biên | E13: Thấp | F13: Có F16 | G13: 1. Play, bấm Next/Previous | H13: Hiện "1 / 1"; nút không gây lỗi.
A14: SS-013 | B14: Hiệu ứng | C14: Animation của shape | D14: Lỗi đã biết | E14: Cao | F14: F07 có hiệu ứng Entrance theo click | G14: 1. Trình chiếu tới slide có hiệu ứng 2. Chạm slide | H14: HIỆN TẠI: KHÔNG có hiệu ứng — slide hiện đầy đủ mọi shape ngay, chạm thì sang slide kế. (Thiết kế mong muốn: shape xuất hiện lần lượt theo hiệu ứng.) | I14: App vẽ slide thành 1 ảnh tĩnh, chưa port trình phát hiệu ứng của app cũ. Không phải lỗi SDK.
A15: SS-014 | B15: Hiệu ứng | C15: Transition giữa các slide | D15: Lỗi đã biết | E15: TB | F15: F07 có transition | G15: 1. Bấm Next | H15: HIỆN TẠI: đổi slide tức thì, không có chuyển cảnh. | I15: Như trên.
A16: SS-015 | B16: Hiệu ứng | C16: Slide ẩn (hidden) | D16: Cần xác nhận | E16: Thấp | F16: Bộ có 1 slide đặt Hidden | G16: 1. Trình chiếu qua vị trí đó | H16: Ghi lại slide ẩn có được chiếu không (PowerPoint sẽ bỏ qua).
A17: SS-016 | B17: Hiệu ứng | C17: Link trên slide | D17: Cần xác nhận | E17: Thấp | F17: Slide có hyperlink | G17: 1. Chạm vào link khi trình chiếu | H17: HIỆN TẠI (dự đoán): chạm sẽ sang slide kế, link không mở. Ghi lại.
A18: SS-017 | B18: Bút vẽ | C18: Vẽ bằng Pen | D18: Chức năng | E18: Cao | F18: Đang trình chiếu | G18: 1. Bấm Pen (nút sáng nền trắng) 2. Vẽ vài nét | H18: Nét đỏ theo ngón tay; chỉ vẽ được trong vùng slide; chạm slide KHÔNG chuyển slide khi Pen bật.
A19: SS-018 | B19: Bút vẽ | C19: Eraser | D19: Chức năng | E19: Cao | F19: Có vài nét vẽ | G19: 1. Bấm Eraser 2. Quét qua 1 nét | H19: Nét bị quét qua biến mất nguyên nét; nút Eraser sáng, Pen tắt.
A20: SS-019 | B20: Bút vẽ | C20: Tắt Pen / Eraser | D20: Chức năng | E20: TB | G20: 1. Bấm lại nút đang bật 2. Chạm slide | H20: Nút tắt sáng; chạm slide lại chuyển slide.
A21: SS-020 | B21: Bút vẽ | C21: Nét vẽ theo từng slide | D21: Chức năng | E21: TB | F21: Vẽ ở slide 2 | G21: 1. Next sang slide 3 2. Previous về slide 2 | H21: Slide 3 không có nét; về slide 2 nét còn nguyên đúng vị trí.
A22: SS-021 | B22: Bút vẽ | C22: Nét vẽ không ghi vào file | D22: Chức năng | E22: TB | F22: Đã vẽ | G22: 1. Exit 2. Xem slide ở chế độ thường, lưu, mở lại | H22: Slide không có nét vẽ; file không đổi. | I22: Nét chỉ tồn tại trong lúc màn hình còn mở.
A23: SS-022 | B23: Bút vẽ | C23: Chuyển slide bằng nút khi Pen đang bật | D23: Chức năng | E23: Thấp | F23: Pen bật | G23: 1. Bấm Next | H23: Sang slide kế, Pen vẫn bật.
A24: SS-023 | B24: Thoát | C24: Thoát bằng nút Exit | D24: Chức năng | E24: Cao | F24: Bắt đầu từ slide 1 ở chế độ xem, chiếu tới slide 4 | G24: 1. Bấm Exit | H24: Màn hình về dọc, chế độ XEM, đang ở slide 4, slide vừa khít chiều rộng (sau khoảng nửa giây).
A25: SS-024 | B25: Thoát | C25: Thoát bằng Back hệ thống | D25: Chức năng | E25: Cao | G25: 1. Bấm Back | H25: Như Exit; KHÔNG thoát khỏi màn Office.
A26: SS-025 | B26: Thoát | C26: Thoát về chế độ sửa | D26: Chức năng | E26: Cao | F26: Bắt đầu trình chiếu từ chế độ sửa | G26: 1. Exit | H26: Về chế độ SỬA (ribbon, dải slide), đúng slide đang chiếu, thay đổi chưa lưu còn nguyên.
A27: SS-026 | B27: Thoát | C27: Thoát rồi vào lại nhiều lần | D27: Biên | E27: TB | G27: 1. Play/Exit 5 lần liên tiếp | H27: Không crash, không kẹt ngang, bố cục dọc đúng mỗi lần.
A28: SS-027 | B28: Vòng đời | C28: Home / khoá màn hình khi đang trình chiếu | D28: Biên | E28: TB | G28: 1. Bấm Home, quay lại 2. Tắt/bật màn hình | H28: Vẫn ở trình chiếu đúng slide, ngang.
A29: SS-028 | B29: Vòng đời | C29: File .ppt cũ | D29: Chức năng | E29: Thấp | F29: Mở F09 | G29: 1. Play | H29: Trình chiếu hoạt động như .pptx.
A30: SS-029 | B30: Vòng đời | C30: Máy tắt tự xoay | D30: Biên | E30: Thấp | F30: Tắt tự xoay màn hình | G30: 1. Bấm Play | H30: Trình chiếu vẫn chuyển sang ngang; Exit về dọc.

Sheet PDF_EndUser
A1: ID bước | B1: Kịch bản | C1: Mục tiêu của người dùng | D1: Chuẩn bị | E1: Người dùng làm gì | F1: Người dùng thấy gì (mong đợi) | G1: Lưu ý | H1: Kết quả | I1: Thực tế / ghi chú của tester | J1: Thiết bị / bản build
A2: P01-01 | B2: P01. Mở và đọc một file PDF | C2: Tôi tải 1 file PDF về và muốn đọc nó. | D2: Đã cấp quyền bộ nhớ. Có D01 (PDF chữ, vài trang). | E2: Mở app, ở tab Files chạm D01. | F2: PDF mở ra. Thanh trên có nút quay lại, tên file, nút tìm kiếm, nút mục lục và nút chế độ đọc. Thanh dưới có: thêm chữ, ghi chú (Annotate), ký (Sign), điền form (Fill), công cụ (Tools). Có nhãn "Page 1 / N" và ô nhỏ "1 / N". | H2: Pass
A3: P01-02 | E3: Vuốt lên để đọc. | F3: Trang cuộn mượt, số trang tăng dần, trang mới nét nhanh. | H3: Pass
A4: P01-03 | E4: Chụm/giãn 2 ngón. | F4: Thu phóng theo tay, chữ nét lại sau khi thả. | H4: Pass
A5: P01-04 | E5: Nhấn giữ vào 1 từ. | F5: Từ được chọn, có 2 tay nắm và kính lúp khi kéo; hiện lựa chọn Copy. | H5: Pass
A6: P01-05 | E6: Kéo tay nắm chọn cả câu, bấm Copy, dán vào app Ghi chú. | F6: Đúng câu đã chọn được dán ra. | H6: Pass
